Workbook
Name Slicer_Request_Month: #N/A
Name Slicer_Shipment_Month: #N/A
Name Slicer_Shipped_Year: #N/A
Name Slicer_Year: #N/A

Sheet PIV
B4: FIELD QUALITY REPORT | T4: Manufacturing Cohort Analysis
B7: Issue Reported Date | C7: (Multiple Items)
B8: Status | C8: (All)
B9: MC Type | C9: (All)
B10: Replacement Type | C10: (All)
B12: Count of MachineSerialNumber | D12: Year | E12: Request Month | T12: Delivered Units to Customer | U12: Pending Number of RMA Units | V12: Field RMA Rate by Cohort
D13: 2025 | L13: 2026 | S13: Total RMA Units
B14: Shipped Year | C14: Shipment Month | D14: May | E14: Jun | F14: Jul | G14: Aug | H14: Sep | I14: Oct | J14: Nov | K14: Dec | L14: Jan | M14: Feb | N14: Mar | O14: Apr | P14: May | Q14: Jun | R14: Jul
B15: 2025 | C15: Jan | D15: 2 | F15: 2 | H15: 1 | I15: 1 | K15: 2 | L15: 3 | M15: 2 | N15: 1 | S15: 14 | T15: - | U15: - | V15: =IFERROR((#REF!+U15)/T15,"")
C16: Feb | D16: 8 | E16: 2 | F16: 2 | G16: 1 | H16: 1 | J16: 1 | K16: 2 | L16: 1 | M16: 5 | S16: 23 | T16: - | U16: - | V16: =IFERROR((#REF!+U16)/T16,"")
C17: Mar | D17: 25 | E17: 2 | F17: 7 | G17: 5 | H17: 2 | I17: 5 | J17: 2 | K17: 2 | L17: 4 | M17: 1 | N17: 1 | O17: 1 | P17: 2 | R17: 1 | S17: 60 | T17: - | U17: - | V17: =IFERROR((#REF!+U17)/T17,"")
C18: Apr | D18: 17 | E18: 31 | F18: 29 | G18: 13 | H18: 18 | I18: 4 | J18: 6 | K18: 2 | L18: 2 | M18: 6 | O18: 1 | P18: 1 | Q18: 1 | R18: 3 | S18: 134 | T18: - | U18: - | V18: =IFERROR((#REF!+U18)/T18,"")
C19: May | D19: 1 | E19: 18 | F19: 20 | G19: 16 | H19: 15 | I19: 5 | J19: 8 | K19: 8 | L19: 7 | M19: 5 | N19: 6 | O19: 2 | P19: 1 | Q19: 2 | R19: 4 | S19: 118 | T19: 138 | U19: 2 | V19: =IFERROR((S19+U19)/T19,"") -> 0.86956522
C20: Jun | E20: 23 | F20: 88 | G20: 84 | H20: 99 | I20: 53 | J20: 50 | K20: 47 | L20: 41 | M20: 33 | N20: 23 | O20: 10 | P20: 9 | Q20: 14 | R20: 21 | S20: 595 | T20: 1004 | U20: 11 | V20: =IFERROR((S20+U20)/T20,"") -> 0.60358566
C21: Jul | E21: 1 | F21: 29 | G21: 81 | H21: 106 | I21: 52 | J21: 59 | K21: 69 | L21: 54 | M21: 51 | N21: 12 | O21: 23 | P21: 23 | Q21: 10 | R21: 30 | S21: 600 | T21: 1081 | U21: 12 | V21: =IFERROR((S21+U21)/T21,"") -> 0.56614246
C22: Aug | F22: 1 | G22: 8 | H22: 96 | I22: 71 | J22: 63 | K22: 65 | L22: 64 | M22: 44 | N22: 5 | O22: 30 | P22: 8 | Q22: 9 | R22: 27 | S22: 491 | T22: 956 | U22: 4 | V22: =IFERROR((S22+U22)/T22,"") -> 0.51778243
C23: Sep | H23: 11 | I23: 40 | J23: 53 | K23: 57 | L23: 44 | M23: 44 | N23: 19 | O23: 26 | P23: 19 | Q23: 12 | R23: 22 | S23: 347 | T23: 840 | U23: 5 | V23: =IFERROR((S23+U23)/T23,"") -> 0.41904762
C24: Oct | H24: 1 | I24: 2 | J24: 42 | K24: 69 | L24: 44 | M24: 43 | N24: 12 | O24: 16 | P24: 19 | Q24: 13 | R24: 25 | S24: 286 | T24: 921 | U24: 9 | V24: =IFERROR((S24+U24)/T24,"") -> 0.32030402
C25: Nov | J25: 5 | K25: 144 | L25: 88 | M25: 92 | N25: 25 | O25: 36 | P25: 36 | Q25: 31 | R25: 40 | S25: 497 | T25: 1742 | U25: 24 | V25: =IFERROR((S25+U25)/T25,"") -> 0.29908152
C26: Dec | K26: 12 | L26: 163 | M26: 131 | N26: 38 | O26: 44 | P26: 37 | Q26: 40 | R26: 53 | S26: 518 | T26: 2242 | U26: 12 | V26: =IFERROR((S26+U26)/T26,"") -> 0.23639607
B27: 2026 | C27: Jan | L27: 1 | M27: 5 | N27: 7 | O27: 17 | P27: 26 | Q27: 24 | R27: 47 | S27: 127 | T27: 278 | U27: 16 | V27: =IFERROR((S27+U27)/T27,"") -> 0.51438849
C28: Feb | M28: 3 | N28: 11 | O28: 36 | P28: 30 | Q28: 16 | R28: 46 | S28: 142 | T28: 786 | U28: 21 | V28: =IFERROR((S28+U28)/T28,"") -> 0.20737913
C29: Mar | P29: 3 | Q29: 7 | R29: 10 | S29: 20 | T29: 598 | U29: 2 | V29: =IFERROR((S29+U29)/T29,"") -> 0.036789298
C30: Apr | P30: 2 | Q30: 14 | R30: 13 | S30: 29 | T30: 733 | U30: 1 | V30: =IFERROR((S30+U30)/T30,"") -> 0.040927694
B31: Total RMA Units | D31: 53 | E31: 77 | F31: 178 | G31: 208 | H31: 350 | I31: 233 | J31: 289 | K31: 479 | L31: 516 | M31: 465 | N31: 160 | O31: 242 | P31: 216 | Q31: 193 | R31: 342 | S31: 4001 | T31: 616
B32: Total Delivered RMA Units | D32: =T19 -> 138 | E32: =T20 -> 1004 | F32: =T21 -> 1081 | G32: =T22 -> 956 | H32: =T23 -> 840 | I32: =T24 -> 921 | J32: =T25 -> 1742 | K32: =T26 -> 2242 | L32: =T27 -> 278 | M32: =T28 -> 786 | N32: =T29 -> 598 | O32: =T30 -> 733 | P32: =T31 -> 616 | Q32: 0 | R32: 0
B33: Active Units in the Field | D33: =D32 -> 138 | E33: =(E32-D31)+D33 -> 1089 | F33: =(F32-E31)+E33 -> 2093 | G33: =(G32-F31)+F33 -> 2871 | H33: =(H32-G31)+G33 -> 3503 | I33: =(I32-H31)+H33 -> 4074 | J33: =(J32-I31)+I33 -> 5583 | K33: =(K32-J31)+J33 -> 7536 | L33: =(L32-K31)+K33 -> 7335 | ... R33: =(R32-Q31)+Q33 -> 8276
B34: Reported Field RMA Rate | D34: =IFERROR(D31/D33,"") -> 0.38405797 | E34: =IFERROR(E31/E33,"") -> 0.070707071 | F34: =IFERROR(F31/F33,"") -> 0.085045389 | G34: =IFERROR(G31/G33,"") -> 0.072448624 | H34: =IFERROR(H31/H33,"") -> 0.099914359 | I34: =IFERROR(I31/I33,"") -> 0.057191949 | J34: =IFERROR(J31/J33,"") -> 0.051764284 | K34: =IFERROR(K31/K33,"") -> 0.063561571 | ... R34: =IFERROR(R31/R33,"") -> 0.041324311
B37: Year | C37: (All)
B38: Request Month | C38: (All)
B40: Shipped Year | C40: Shipment Month | D40: WW Code | E40: Count of MachineSerialNumber
B41: 2025 | C41: Jan | D41: 04 | E41: 4
D42: 09 | E42: 7
D43: CA | E43: 2
D44: ME | E44: 1
C45: Feb | D45: 08 | E45: 3
D46: 09 | E46: 12
D47: 13 | E47: 1
D48: 1C | E48: 3
D49: CA | E49: 4
...

Sheet Product Performance
B2: Field Quality Report | J2: Manufacturing Cohort Analysis | Q2: Cummulative Quarterly Performance Per Manufacturing Cohort | AG2: Cumulative RMA Failure Rate by Manufacturing Cohort and Aging Interval | BA2: Failure.Failure Category | BB2: Count of MachineSerialNumber | BD2: Failure.Failure Mode | BE2: Count of MachineSerialNumber
B3: Shipment Year | C3: Shipment Month | D3: Total RMA Units | E3: Total Delivered RMA Units | F3: Active Units in the Field | G3: Reported Field RMA Rate | J3: Shipment Year | K3: Shipment Month | L3: Total RMA Units | M3: Delivered Units to Customer | N3: Pending Number of RMA Units | O3: Field RMA Rate by Cohort | Q3: Year | R3: Quarter | S3: Delivered Units | T3: M0 (3-month offset) | U3: M+1 | V3: M+2 | W3: M+3 | X3: M+4 | Y3: M+5 | Z3: M+6 | AA3: M+7 | AB3: M+8 | AC3: M+9 | AD3: M+10 | AE3: M+11 | AG3: Shipment Year | AH3: Shipment Month | AI3: Delivered Units | AJ3: 0–3 Months | AK3: 3–6 Months | AL3: 6–9 Months | AM3: 9–12 Months | AN3: 12–15 Months | AO3: 15–18 Months | BA3: Kicker Module | BB3: 1060 | BD3: Not Powering On | BE3: 699
B4: 2025 | C4: May | D4: 53 | E4: 138 | F4: 138 | G4: 0.38405797 | J4: 2025 | K4: May | L4: 114 | M4: 138 | N4: 2 | O4: 0.84057971 | Q4: 2025 | R4: Qtr2 | S4: 1142 | T4: 0.20490368 | U4: 0.3056042 | V4: 0.36514886 | W4: 0.41330998 | X4: 0.4614711 | Y4: 0.50437828 | Z4: 0.53940455 | AA4: 0.56392294 | AB4: 0.57793345 | AC4: 0.58756567 | AD4: 0.60070053 | AE4: 0.61646235 | AG4: 2025 | AH4: May | AI4: 138 | AJ4: =IF(SUM(OFFSET($T$50,0,(COLUMN()-COLUMN($AJ$4))*3,1,3))=0,"",SUM(OFFSET($T$50,0,(COLUMN()-COLUMN($AJ$4))*3,1,3))) -> 0.2826087 | AK4: =IFERROR(IF(SUM(OFFSET($T$50,0,(COLUMN()-COLUMN($AJ$4))*3,1,3))=0,"",SUM(OFFSET($T$50,0,(COLUMN()-COLUMN($AJ$4))*3,1,3)))+AJ4,"") -> 0.54347826 | AL4: =IFERROR(IF(SUM(OFFSET($T$50,0,(COLUMN()-COLUMN($AJ$4))*3,1,3))=0,"",SUM(OFFSET($T$50,0,(COLUMN()-COLUMN($AJ$4))*3,1,3)))+AK4,"") -> 0.71014493 | AM4: =IFERROR(IF(SUM(OFFSET($T$50,0,(COLUMN()-COLUMN($AJ$4))*3,1,3))=0,"",SUM(OFFSET($T$50,0,(COLUMN()-COLUMN($AJ$4))*3,1,3)))+AL4,"") -> 0.80434783 | AN4: =IFERROR(IF(SUM(OFFSET($T$50,0,(COLUMN()-COLUMN($AJ$4))*3,1,3))=0,"",SUM(OFFSET($T$50,0,(COLUMN()-COLUMN($AJ$4))*3,1,3)))+AM4,"") -> 0.85507246 | AO4: =IFERROR(IF(SUM(OFFSET($T$50,0,(COLUMN()-COLUMN($AJ$4))*3,1,3))=0,"",SUM(OFFSET($T$50,0,(COLUMN()-COLUMN($AJ$4))*3,1,3)))+AN4,"") | BA4: Electrical | BB4: 797 | BD4: Kicker Drive | BE4: 617
C5: Jun | D5: 77 | E5: 1004 | F5: 1089 | G5: 0.070707071 | K5: Jun | L5: 574 | M5: 1004 | N5: 11 | O5: 0.58266932 | R5: Qtr3 | S5: 2877 | T5: 0.17274939 | U5: 0.23253389 | V5: 0.29092805 | W5: 0.35245047 | X5: 0.39311783 | Y5: 0.42161974 | Z5: 0.44282238 | AA5: 0.45776851 | AB5: 0.47480014 | AC5: 0.48522767 | AH5: Jun | AI5: 1004 | AJ5: =IF(SUM(OFFSET($U$51,0,(COLUMN()-COLUMN($AJ$4))*3,1,3))=0,"",SUM(OFFSET($U$51,0,(COLUMN()-COLUMN($AJ$4))*3,1,3))) -> 0.19422311 | AK5: =IFERROR(IF(SUM(OFFSET($U$51,0,(COLUMN()-COLUMN($AJ$4))*3,1,3))=0,"",SUM(OFFSET($U$51,0,(COLUMN()-COLUMN($AJ$4))*3,1,3)))+AJ5,"") -> 0.39541833 | AL5: =IFERROR(IF(SUM(OFFSET($U$51,0,(COLUMN()-COLUMN($AJ$4))*3,1,3))=0,"",SUM(OFFSET($U$51,0,(COLUMN()-COLUMN($AJ$4))*3,1,3)))+AK5,"") -> 0.51593625 | AM5: =IFERROR(IF(SUM(OFFSET($U$51,0,(COLUMN()-COLUMN($AJ$4))*3,1,3))=0,"",SUM(OFFSET($U$51,0,(COLUMN()-COLUMN($AJ$4))*3,1,3)))+AL5,"") -> 0.55776892 | AN5: =IFERROR(IF(SUM(OFFSET($U$51,0,(COLUMN()-COLUMN($AJ$4))*3,1,3))=0,"",SUM(OFFSET($U$51,0,(COLUMN()-COLUMN($AJ$4))*3,1,3)))+AM5,"") -> 0.59262948 | AO5: =IFERROR(IF(SUM(OFFSET($U$51,0,(COLUMN()-COLUMN($AJ$4))*3,1,3))=0,"",SUM(OFFSET($U$51,0,(COLUMN()-COLUMN($AJ$4))*3,1,3)))+AN5,"") | BA5: Kneader | BB5: 355 | BD5: Administrative Note | BE5: 268
C6: Jul | D6: 178 | E6: 1081 | F6: 2093 | G6: 0.085045389 | K6: Jul | L6: 582 | M6: 1081 | N6: 12 | O6: 0.54949121 | R6: Qtr4 | S6: 4905 | T6: 0.13394495 | U6: 0.16941896 | V6: 0.19245668 | W6: 0.20998981 | X6: 0.22895005 | Y6: 0.2479103 | Z6: 0.25688073 | AA6: 0.26055046 | AH6: Jul | AI6: 1081 | AJ6: =IF(SUM(OFFSET($V$52,0,(COLUMN()-COLUMN($AJ$4))*3,1,3))=0,"",SUM(OFFSET($V$52,0,(COLUMN()-COLUMN($AJ$4))*3,1,3))) -> 0.19981499 | AK6: =IFERROR(IF(SUM(OFFSET($V$52,0,(COLUMN()-COLUMN($AJ$4))*3,1,3))=0,"",SUM(OFFSET($V$52,0,(COLUMN()-COLUMN($AJ$4))*3,1,3)))+AJ6,"") -> 0.36632747 | AL6: =IFERROR(IF(SUM(OFFSET($V$52,0,(COLUMN()-COLUMN($AJ$4))*3,1,3))=0,"",SUM(OFFSET($V$52,0,(COLUMN()-COLUMN($AJ$4))*3,1,3)))+AK6,"") -> 0.47456059 | AM6: =IFERROR(IF(SUM(OFFSET($V$52,0,(COLUMN()-COLUMN($AJ$4))*3,1,3))=0,"",SUM(OFFSET($V$52,0,(COLUMN()-COLUMN($AJ$4))*3,1,3)))+AL6,"") -> 0.52636448 | AN6: =IFERROR(IF(SUM(OFFSET($V$52,0,(COLUMN()-COLUMN($AJ$4))*3,1,3))=0,"",SUM(OFFSET($V$52,0,(COLUMN()-COLUMN($AJ$4))*3,1,3)))+AM6,"") -> 0.55411656 | AO6: =IFERROR(IF(SUM(OFFSET($V$52,0,(COLUMN()-COLUMN($AJ$4))*3,1,3))=0,"",SUM(OFFSET($V$52,0,(COLUMN()-COLUMN($AJ$4))*3,1,3)))+AN6,"") | BA6: Administrative | BB6: 296 | BD6: Kicker Noise | BE6: 225
C7: Aug | D7: 208 | E7: 956 | F7: 2871 | G7: 0.072448624 | K7: Aug | L7: 465 | M7: 956 | N7: 4 | O7: 0.49058577 | Q7: 2026 | R7: Qtr1 | S7: 1662 | T7: 0.039711191 | U7: 0.072803851 | V7: 0.10168472 | W7: 0.13658243 | X7: 0.16185319 | AH7: Aug | AI7: 956 | AJ7: =IF(SUM(OFFSET($W$53,0,(COLUMN()-COLUMN($AJ$4))*3,1,3))=0,"",SUM(OFFSET($W$53,0,(COLUMN()-COLUMN($AJ$4))*3,1,3))) -> 0.18305439 | AK7: =IFERROR(IF(SUM(OFFSET($W$53,0,(COLUMN()-COLUMN($AJ$4))*3,1,3))=0,"",SUM(OFFSET($W$53,0,(COLUMN()-COLUMN($AJ$4))*3,1,3)))+AJ7,"") -> 0.38389121 | AL7: =IFERROR(IF(SUM(OFFSET($W$53,0,(COLUMN()-COLUMN($AJ$4))*3,1,3))=0,"",SUM(OFFSET($W$53,0,(COLUMN()-COLUMN($AJ$4))*3,1,3)))+AK7,"") -> 0.4665272 | AM7: =IFERROR(IF(SUM(OFFSET($W$53,0,(COLUMN()-COLUMN($AJ$4))*3,1,3))=0,"",SUM(OFFSET($W$53,0,(COLUMN()-COLUMN($AJ$4))*3,1,3)))+AL7,"") -> 0.5125523 | AN7: =IFERROR(IF(SUM(OFFSET($W$53,0,(COLUMN()-COLUMN($AJ$4))*3,1,3))=0,"",SUM(OFFSET($W$53,0,(COLUMN()-COLUMN($AJ$4))*3,1,3)))+AM7,"") | AO7: =IFERROR(IF(SUM(OFFSET($W$53,0,(COLUMN()-COLUMN($AJ$4))*3,1,3))=0,"",SUM(OFFSET($W$53,0,(COLUMN()-COLUMN($AJ$4))*3,1,3)))+AN7,"") | BA7: Ingredient System | BB7: 270 | BD7: Roti Quality Issue | BE7: 200
C8: Sep | D8: 350 | E8: 840 | F8: 3503 | G8: 0.099914359 | K8: Sep | L8: 319 | M8: 840 | N8: 5 | O8: 0.38571429 | R8: Qtr2 | S8: 1349 | T8: 0.011860638 | U8: 0.018532246 | AH8: Sep | AI8: 840 | AJ8: =IF(SUM(OFFSET($X$54,0,(COLUMN()-COLUMN($AJ$4))*3,1,3))=0,"",SUM(OFFSET($X$54,0,(COLUMN()-COLUMN($AJ$4))*3,1,3))) -> 0.12380952 | AK8: =IFERROR(IF(SUM(OFFSET($X$54,0,(COLUMN()-COLUMN($AJ$4))*3,1,3))=0,"",SUM(OFFSET($X$54,0,(COLUMN()-COLUMN($AJ$4))*3,1,3)))+AJ8,"") -> 0.29642857 | AL8: =IFERROR(IF(SUM(OFFSET($X$54,0,(COLUMN()-COLUMN($AJ$4))*3,1,3))=0,"",SUM(OFFSET($X$54,0,(COLUMN()-COLUMN($AJ$4))*3,1,3)))+AK8,"") -> 0.37261905 | AM8: =IFERROR(IF(SUM(OFFSET($X$54,0,(COLUMN()-COLUMN($AJ$4))*3,1,3))=0,"",SUM(OFFSET($X$54,0,(COLUMN()-COLUMN($AJ$4))*3,1,3)))+AL8,"") -> 0.41309524 | AN8: =IFERROR(IF(SUM(OFFSET($X$54,0,(COLUMN()-COLUMN($AJ$4))*3,1,3))=0,"",SUM(OFFSET($X$54,0,(COLUMN()-COLUMN($AJ$4))*3,1,3)))+AM8,"") | AO8: =IFERROR(IF(SUM(OFFSET($X$54,0,(COLUMN()-COLUMN($AJ$4))*3,1,3))=0,"",SUM(OFFSET($X$54,0,(COLUMN()-COLUMN($AJ$4))*3,1,3)))+AN8,"") | BA8: Heating/Cooking | BB8: 250 | BD8: Kicker Catcher Issue | BE8: 197
C9: Oct | D9: 233 | E9: 921 | F9: 4074 | G9: 0.057191949 | K9: Oct | L9: 258 | M9: 921 | N9: 9 | O9: 0.28990228 | R9: Qtr3 | S9: 0 | AH9: Oct | AI9: 921 | AJ9: =IF(SUM(OFFSET($Y$55,0,(COLUMN()-COLUMN($AJ$4))*3,1,3))=0,"",SUM(OFFSET($Y$55,0,(COLUMN()-COLUMN($AJ$4))*3,1,3))) -> 0.12269273 | AK9: =IFERROR(IF(SUM(OFFSET($Y$55,0,(COLUMN()-COLUMN($AJ$4))*3,1,3))=0,"",SUM(OFFSET($Y$55,0,(COLUMN()-COLUMN($AJ$4))*3,1,3)))+AJ9,"") -> 0.23018458 | AL9: =IFERROR(IF(SUM(OFFSET($Y$55,0,(COLUMN()-COLUMN($AJ$4))*3,1,3))=0,"",SUM(OFFSET($Y$55,0,(COLUMN()-COLUMN($AJ$4))*3,1,3)))+AK9,"") -> 0.28230185 | AM9: =IFERROR(IF(SUM(OFFSET($Y$55,0,(COLUMN()-COLUMN($AJ$4))*3,1,3))=0,"",SUM(OFFSET($Y$55,0,(COLUMN()-COLUMN($AJ$4))*3,1,3)))+AL9,"") -> 0.30944625 | AN9: =IFERROR(IF(SUM(OFFSET($Y$55,0,(COLUMN()-COLUMN($AJ$4))*3,1,3))=0,"",SUM(OFFSET($Y$55,0,(COLUMN()-COLUMN($AJ$4))*3,1,3)))+AM9,"") | AO9: =IFERROR(IF(SUM(OFFSET($Y$55,0,(COLUMN()-COLUMN($AJ$4))*3,1,3))=0,"",SUM(OFFSET($Y$55,0,(COLUMN()-COLUMN($AJ$4))*3,1,3)))+AN9,"") | BA9: Logistics | BB9: 236 | BD9: Kneader Blade Stuck | BE9: 175
C10: Nov | D10: 289 | E10: 1742 | F10: 5583 | G10: 0.051764284 | K10: Nov | L10: 391 | M10: 1742 | N10: 24 | O10: 0.23823192 | R10: Qtr4 | S10: 0 | AH10: Nov | AI10: 1742 | AJ10: =IF(SUM(OFFSET($Z$56,0,(COLUMN()-COLUMN($AJ$4))*3,1,3))=0,"",SUM(OFFSET($Z$56,0,(COLUMN()-COLUMN($AJ$4))*3,1,3))) -> 0.13605052 | AK10: =IFERROR(IF(SUM(OFFSET($Z$56,0,(COLUMN()-COLUMN($AJ$4))*3,1,3))=0,"",SUM(OFFSET($Z$56,0,(COLUMN()-COLUMN($AJ$4))*3,1,3)))+AJ10,"") -> 0.2238806 | AL10: =IFERROR(IF(SUM(OFFSET($Z$56,0,(COLUMN()-COLUMN($AJ$4))*3,1,3))=0,"",SUM(OFFSET($Z$56,0,(COLUMN()-COLUMN($AJ$4))*3,1,3)))+AK10,"") -> 0.28530425 | AM10: =IFERROR(IF(SUM(OFFSET($Z$56,0,(COLUMN()-COLUMN($AJ$4))*3,1,3))=0,"",SUM(OFFSET($Z$56,0,(COLUMN()-COLUMN($AJ$4))*3,1,3)))+AL10,"") | AN10: =IFERROR(IF(SUM(OFFSET($Z$56,0,(COLUMN()-COLUMN($AJ$4))*3,1,3))=0,"",SUM(OFFSET($Z$56,0,(COLUMN()-COLUMN($AJ$4))*3,1,3)))+AM10,"") | AO10: =IFERROR(IF(SUM(OFFSET($Z$56,0,(COLUMN()-COLUMN($AJ$4))*3,1,3))=0,"",SUM(OFFSET($Z$56,0,(COLUMN()-COLUMN($AJ$4))*3,1,3)))+AN10,"") | BA10: Press Pan Module | BB10: 166 | BD10: Cracked Machine | BE10: 139
C11: Dec | D11: 409 | E11: 2242 | F11: 7536 | G11: 0.054272824 | K11: Dec | L11: 360 | M11: 2242 | N11: 12 | O11: 0.16592328 | AH11: Dec | AI11: 2242 | AJ11: =IF(SUM(OFFSET($AA$57,0,(COLUMN()-COLUMN($AJ$4))*3,1,3))=0,"",SUM(OFFSET($AA$57,0,(COLUMN()-COLUMN($AJ$4))*3,1,3))) -> 0.13648528 | AK11: =IFERROR(IF(SUM(OFFSET($AA$57,0,(COLUMN()-COLUMN($AJ$4))*3,1,3))=0,"",SUM(OFFSET($AA$57,0,(COLUMN()-COLUMN($AJ$4))*3,1,3)))+AJ11,"") -> 0.18956289 | AL11: =IFERROR(IF(SUM(OFFSET($AA$57,0,(COLUMN()-COLUMN($AJ$4))*3,1,3))=0,"",SUM(OFFSET($AA$57,0,(COLUMN()-COLUMN($AJ$4))*3,1,3)))+AK11,"") -> 0.23104371 | AM11: =IFERROR(IF(SUM(OFFSET($AA$57,0,(COLUMN()-COLUMN($AJ$4))*3,1,3))=0,"",SUM(OFFSET($AA$57,0,(COLUMN()-COLUMN($AJ$4))*3,1,3)))+AL11,"") | AN11: =IFERROR(IF(SUM(OFFSET($AA$57,0,(COLUMN()-COLUMN($AJ$4))*3,1,3))=0,"",SUM(OFFSET($AA$57,0,(COLUMN()-COLUMN($AJ$4))*3,1,3)))+AM11,"") | AO11: =IFERROR(IF(SUM(OFFSET($AA$57,0,(COLUMN()-COLUMN($AJ$4))*3,1,3))=0,"",SUM(OFFSET($AA$57,0,(COLUMN()-COLUMN($AJ$4))*3,1,3)))+AN11,"") | BA11: Customer Service | BB11: 127 | BD11: Kneader Stuck | BE11: 120
B12: 2026 | C12: Jan | D12: 430 | E12: 278 | F12: 7405 | G12: 0.058068872 | J12: 2026 | K12: Jan | L12: 88 | M12: 278 | N12: 16 | O12: 0.37410072 | AG12: 2026 | AH12: Jan | AI12: 278 | AJ12: =IF(SUM(OFFSET($AB$58,0,(COLUMN()-COLUMN($AJ$4))*3,1,3))=0,"",SUM(OFFSET($AB$58,0,(COLUMN()-COLUMN($AJ$4))*3,1,3))) -> 0.04676259 | AK12: =IFERROR(IF(SUM(OFFSET($AB$58,0,(COLUMN()-COLUMN($AJ$4))*3,1,3))=0,"",SUM(OFFSET($AB$58,0,(COLUMN()-COLUMN($AJ$4))*3,1,3)))+AJ12,"") -> 0.28776978 | AL12: =IFERROR(IF(SUM(OFFSET($AB$58,0,(COLUMN()-COLUMN($AJ$4))*3,1,3))=0,"",SUM(OFFSET($AB$58,0,(COLUMN()-COLUMN($AJ$4))*3,1,3)))+AK12,"") -> 0.45683453 | AM12: =IFERROR(IF(SUM(OFFSET($AB$58,0,(COLUMN()-COLUMN($AJ$4))*3,1,3))=0,"",SUM(OFFSET($AB$58,0,(COLUMN()-COLUMN($AJ$4))*3,1,3)))+AL12,"") | AN12: =IFERROR(IF(SUM(OFFSET($AB$58,0,(COLUMN()-COLUMN($AJ$4))*3,1,3))=0,"",SUM(OFFSET($AB$58,0,(COLUMN()-COLUMN($AJ$4))*3,1,3)))+AM12,"") | AO12: =IFERROR(IF(SUM(OFFSET($AB$58,0,(COLUMN()-COLUMN($AJ$4))*3,1,3))=0,"",SUM(OFFSET($AB$58,0,(COLUMN()-COLUMN($AJ$4))*3,1,3)))+AN12,"") | BA12: VT Module | BB12: 65 | BD12: Press Pan Malfunction | BE12: 100
C13: Feb | D13: 395 | E13: 786 | F13: 7761 | G13: 0.050895503 | K13: Feb | L13: 112 | M13: 786 | N13: 21 | O13: 0.1692112 | AH13: Feb | AI13: 786 | AJ13: =IF(SUM(OFFSET($AC$59,0,(COLUMN()-COLUMN($AJ$4))*3,1,3))=0,"",SUM(OFFSET($AC$59,0,(COLUMN()-COLUMN($AJ$4))*3,1,3))) -> 0.063613232 | AK13: =IFERROR(IF(SUM(OFFSET($AC$59,0,(COLUMN()-COLUMN($AJ$4))*3,1,3))=0,"",SUM(OFFSET($AC$59,0,(COLUMN()-COLUMN($AJ$4))*3,1,3)))+AJ13,"") -> 0.18066158 | AL13: =IFERROR(IF(SUM(OFFSET($AC$59,0,(COLUMN()-COLUMN($AJ$4))*3,1,3))=0,"",SUM(OFFSET($AC$59,0,(COLUMN()-COLUMN($AJ$4))*3,1,3)))+AK13,"") | AM13: =IFERROR(IF(SUM(OFFSET($AC$59,0,(COLUMN()-COLUMN($AJ$4))*3,1,3))=0,"",SUM(OFFSET($AC$59,0,(COLUMN()-COLUMN($AJ$4))*3,1,3)))+AL13,"") | AN13: =IFERROR(IF(SUM(OFFSET($AC$59,0,(COLUMN()-COLUMN($AJ$4))*3,1,3))=0,"",SUM(OFFSET($AC$59,0,(COLUMN()-COLUMN($AJ$4))*3,1,3)))+AM13,"") | AO13: =IFERROR(IF(SUM(OFFSET($AC$59,0,(COLUMN()-COLUMN($AJ$4))*3,1,3))=0,"",SUM(OFFSET($AC$59,0,(COLUMN()-COLUMN($AJ$4))*3,1,3)))+AN13,"") | BA13: Grand Total | BB13: 3622 | BD13: Grand Total | BE13: 2740
C14: Mar | D14: 134 | E14: 598 | F14: 7964 | G14: 0.016825716 | K14: Mar | L14: 16 | M14: 598 | N14: 2 | O14: 0.030100334 | AH14: Mar | AI14: 598 | AJ14: =IF(SUM(OFFSET($AD$60,0,(COLUMN()-COLUMN($AJ$4))*3,1,3))=0,"",SUM(OFFSET($AD$60,0,(COLUMN()-COLUMN($AJ$4))*3,1,3))) -> 0.0050167224 | AK14: =IFERROR(IF(SUM(OFFSET($AD$60,0,(COLUMN()-COLUMN($AJ$4))*3,1,3))=0,"",SUM(OFFSET($AD$60,0,(COLUMN()-COLUMN($AJ$4))*3,1,3)))+AJ14,"") -> 0.033444816 | AL14: =IFERROR(IF(SUM(OFFSET($AD$60,0,(COLUMN()-COLUMN($AJ$4))*3,1,3))=0,"",SUM(OFFSET($AD$60,0,(COLUMN()-COLUMN($AJ$4))*3,1,3)))+AK14,"") | AM14: =IFERROR(IF(SUM(OFFSET($AD$60,0,(COLUMN()-COLUMN($AJ$4))*3,1,3))=0,"",SUM(OFFSET($AD$60,0,(COLUMN()-COLUMN($AJ$4))*3,1,3)))+AL14,"") | AN14: =IFERROR(IF(SUM(OFFSET($AD$60,0,(COLUMN()-COLUMN($AJ$4))*3,1,3))=0,"",SUM(OFFSET($AD$60,0,(COLUMN()-COLUMN($AJ$4))*3,1,3)))+AM14,"") | AO14: =IFERROR(IF(SUM(OFFSET($AD$60,0,(COLUMN()-COLUMN($AJ$4))*3,1,3))=0,"",SUM(OFFSET($AD$60,0,(COLUMN()-COLUMN($AJ$4))*3,1,3)))+AN14,"")
C15: Apr | D15: 205 | E15: 733 | F15: 8563 | G15: 0.023940208 | K15: Apr | L15: 17 | M15: 733 | N15: 1 | O15: 0.024556617 | AH15: Apr | AI15: 733 | AJ15: =IF(SUM(OFFSET($AE$61,0,(COLUMN()-COLUMN($AJ$4))*3,1,3))=0,"",SUM(OFFSET($AE$61,0,(COLUMN()-COLUMN($AJ$4))*3,1,3))) -> 0.021828104 | AK15: =IFERROR(IF(SUM(OFFSET($AE$61,0,(COLUMN()-COLUMN($AJ$4))*3,1,3))=0,"",SUM(OFFSET($AE$61,0,(COLUMN()-COLUMN($AJ$4))*3,1,3)))+AJ15,"") -> 0.039563438 | AL15: =IFERROR(IF(SUM(OFFSET($AE$61,0,(COLUMN()-COLUMN($AJ$4))*3,1,3))=0,"",SUM(OFFSET($AE$61,0,(COLUMN()-COLUMN($AJ$4))*3,1,3)))+AK15,"") | AM15: =IFERROR(IF(SUM(OFFSET($AE$61,0,(COLUMN()-COLUMN($AJ$4))*3,1,3))=0,"",SUM(OFFSET($AE$61,0,(COLUMN()-COLUMN($AJ$4))*3,1,3)))+AL15,"") | AN15: =IFERROR(IF(SUM(OFFSET($AE$61,0,(COLUMN()-COLUMN($AJ$4))*3,1,3))=0,"",SUM(OFFSET($AE$61,0,(COLUMN()-COLUMN($AJ$4))*3,1,3)))+AM15,"") | AO15: =IFERROR(IF(SUM(OFFSET($AE$61,0,(COLUMN()-COLUMN($AJ$4))*3,1,3))=0,"",SUM(OFFSET($AE$61,0,(COLUMN()-COLUMN($AJ$4))*3,1,3)))+AN15,"")
C16: May | D16: 148 | E16: 616 | F16: 8974 | G16: 0.016492088
C17: Jun | D17: 113 | E17: 0 | F17: 8826 | G17: 0.012803082
C18: Jul | D18: 298 | E18: 0 | F18: 8713 | G18: 0.034201767
Q47: Cumulative Manufacturing Cohort Heatmap
Q48: Year | R48: Month | S48: Delivered Units | T48: 2025 | AB48: 2026
T49: May | U49: Jun | V49: Jul | W49: Aug | X49: Sep | Y49: Oct | Z49: Nov | AA49: Dec | AB49: Jan | AC49: Feb | AD49: Mar | AE49: Apr | AF49: May | AG49: Jun | AH49: Jul | AI49: Aug | AJ49: Sep | AK49: Oct | AL49: Nov | AM49: Dec
Q50: 2025 | R50: May | S50: 138 | T50: =IF(IFERROR(PIV!D19/PIV!$T19,"")=0,"",IFERROR(PIV!D19/PIV!$T19,"")) -> 0.0072463768 | U50: =IF(IFERROR(PIV!E19/PIV!$T19,"")=0,"",IFERROR(PIV!E19/PIV!$T19,"")) -> 0.13043478 | V50: =IF(IFERROR(PIV!F19/PIV!$T19,"")=0,"",IFERROR(PIV!F19/PIV!$T19,"")) -> 0.14492754 | W50: =IF(IFERROR(PIV!G19/PIV!$T19,"")=0,"",IFERROR(PIV!G19/PIV!$T19,"")) -> 0.11594203 | X50: =IF(IFERROR(PIV!H19/PIV!$T19,"")=0,"",IFERROR(PIV!H19/PIV!$T19,"")) -> 0.10869565 | Y50: =IF(IFERROR(PIV!I19/PIV!$T19,"")=0,"",IFERROR(PIV!I19/PIV!$T19,"")) -> 0.036231884 | Z50: =IF(IFERROR(PIV!J19/PIV!$T19,"")=0,"",IFERROR(PIV!J19/PIV!$T19,"")) -> 0.057971014 | AA50: =IF(IFERROR(PIV!K19/PIV!$T19,"")=0,"",IFERROR(PIV!K19/PIV!$T19,"")) -> 0.057971014 | ... AH50: =IF(IFERROR(PIV!R19/PIV!$T19,"")=0,"",IFERROR(PIV!R19/PIV!$T19,"")) -> 0.028985507
R51: Jun | S51: 1004 | T51: =IF(IFERROR(PIV!D20/PIV!$T20,"")=0,"",IFERROR(PIV!D20/PIV!$T20,"")) | U51: =IF(IFERROR(PIV!E20/PIV!$T20,"")=0,"",IFERROR(PIV!E20/PIV!$T20,"")) -> 0.022908367 | V51: =IF(IFERROR(PIV!F20/PIV!$T20,"")=0,"",IFERROR(PIV!F20/PIV!$T20,"")) -> 0.087649402 | W51: =IF(IFERROR(PIV!G20/PIV!$T20,"")=0,"",IFERROR(PIV!G20/PIV!$T20,"")) -> 0.083665339 | X51: =IF(IFERROR(PIV!H20/PIV!$T20,"")=0,"",IFERROR(PIV!H20/PIV!$T20,"")) -> 0.098605578 | Y51: =IF(IFERROR(PIV!I20/PIV!$T20,"")=0,"",IFERROR(PIV!I20/PIV!$T20,"")) -> 0.052788845 | Z51: =IF(IFERROR(PIV!J20/PIV!$T20,"")=0,"",IFERROR(PIV!J20/PIV!$T20,"")) -> 0.049800797 | AA51: =IF(IFERROR(PIV!K20/PIV!$T20,"")=0,"",IFERROR(PIV!K20/PIV!$T20,"")) -> 0.046812749 | ... AH51: =IF(IFERROR(PIV!R20/PIV!$T20,"")=0,"",IFERROR(PIV!R20/PIV!$T20,"")) -> 0.020916335
R52: Jul | S52: 1081 | T52: =IF(IFERROR(PIV!D21/PIV!$T21,"")=0,"",IFERROR(PIV!D21/PIV!$T21,"")) | U52: =IF(IFERROR(PIV!E21/PIV!$T21,"")=0,"",IFERROR(PIV!E21/PIV!$T21,"")) -> 0.00092506938 | V52: =IF(IFERROR(PIV!F21/PIV!$T21,"")=0,"",IFERROR(PIV!F21/PIV!$T21,"")) -> 0.026827012 | W52: =IF(IFERROR(PIV!G21/PIV!$T21,"")=0,"",IFERROR(PIV!G21/PIV!$T21,"")) -> 0.07493062 | X52: =IF(IFERROR(PIV!H21/PIV!$T21,"")=0,"",IFERROR(PIV!H21/PIV!$T21,"")) -> 0.098057354 | Y52: =IF(IFERROR(PIV!I21/PIV!$T21,"")=0,"",IFERROR(PIV!I21/PIV!$T21,"")) -> 0.048103608 | Z52: =IF(IFERROR(PIV!J21/PIV!$T21,"")=0,"",IFERROR(PIV!J21/PIV!$T21,"")) -> 0.054579093 | AA52: =IF(IFERROR(PIV!K21/PIV!$T21,"")=0,"",IFERROR(PIV!K21/PIV!$T21,"")) -> 0.063829787 | ... AH52: =IF(IFERROR(PIV!R21/PIV!$T21,"")=0,"",IFERROR(PIV!R21/PIV!$T21,"")) -> 0.027752081
R53: Aug | S53: 956 | T53: =IF(IFERROR(PIV!D22/PIV!$T22,"")=0,"",IFERROR(PIV!D22/PIV!$T22,"")) | U53: =IF(IFERROR(PIV!E22/PIV!$T22,"")=0,"",IFERROR(PIV!E22/PIV!$T22,"")) | V53: =IF(IFERROR(PIV!F22/PIV!$T22,"")=0,"",IFERROR(PIV!F22/PIV!$T22,"")) -> 0.0010460251 | W53: =IF(IFERROR(PIV!G22/PIV!$T22,"")=0,"",IFERROR(PIV!G22/PIV!$T22,"")) -> 0.0083682008 | X53: =IF(IFERROR(PIV!H22/PIV!$T22,"")=0,"",IFERROR(PIV!H22/PIV!$T22,"")) -> 0.10041841 | Y53: =IF(IFERROR(PIV!I22/PIV!$T22,"")=0,"",IFERROR(PIV!I22/PIV!$T22,"")) -> 0.074267782 | Z53: =IF(IFERROR(PIV!J22/PIV!$T22,"")=0,"",IFERROR(PIV!J22/PIV!$T22,"")) -> 0.065899582 | AA53: =IF(IFERROR(PIV!K22/PIV!$T22,"")=0,"",IFERROR(PIV!K22/PIV!$T22,"")) -> 0.067991632 | ... AH53: =IF(IFERROR(PIV!R22/PIV!$T22,"")=0,"",IFERROR(PIV!R22/PIV!$T22,"")) -> 0.028242678
R54: Sep | S54: 840 | T54: =IF(IFERROR(PIV!D23/PIV!$T23,"")=0,"",IFERROR(PIV!D23/PIV!$T23,"")) | U54: =IF(IFERROR(PIV!E23/PIV!$T23,"")=0,"",IFERROR(PIV!E23/PIV!$T23,"")) | V54: =IF(IFERROR(PIV!F23/PIV!$T23,"")=0,"",IFERROR(PIV!F23/PIV!$T23,"")) | W54: =IF(IFERROR(PIV!G23/PIV!$T23,"")=0,"",IFERROR(PIV!G23/PIV!$T23,"")) | X54: =IF(IFERROR(PIV!H23/PIV!$T23,"")=0,"",IFERROR(PIV!H23/PIV!$T23,"")) -> 0.013095238 | Y54: =IF(IFERROR(PIV!I23/PIV!$T23,"")=0,"",IFERROR(PIV!I23/PIV!$T23,"")) -> 0.047619048 | Z54: =IF(IFERROR(PIV!J23/PIV!$T23,"")=0,"",IFERROR(PIV!J23/PIV!$T23,"")) -> 0.063095238 | AA54: =IF(IFERROR(PIV!K23/PIV!$T23,"")=0,"",IFERROR(PIV!K23/PIV!$T23,"")) -> 0.067857143 | ... AH54: =IF(IFERROR(PIV!R23/PIV!$T23,"")=0,"",IFERROR(PIV!R23/PIV!$T23,"")) -> 0.026190476
R55: Oct | S55: 921 | T55: =IF(IFERROR(PIV!D24/PIV!$T24,"")=0,"",IFERROR(PIV!D24/PIV!$T24,"")) | U55: =IF(IFERROR(PIV!E24/PIV!$T24,"")=0,"",IFERROR(PIV!E24/PIV!$T24,"")) | V55: =IF(IFERROR(PIV!F24/PIV!$T24,"")=0,"",IFERROR(PIV!F24/PIV!$T24,"")) | W55: =IF(IFERROR(PIV!G24/PIV!$T24,"")=0,"",IFERROR(PIV!G24/PIV!$T24,"")) | X55: =IF(IFERROR(PIV!H24/PIV!$T24,"")=0,"",IFERROR(PIV!H24/PIV!$T24,"")) -> 0.0010857763 | Y55: =IF(IFERROR(PIV!I24/PIV!$T24,"")=0,"",IFERROR(PIV!I24/PIV!$T24,"")) -> 0.0021715527 | Z55: =IF(IFERROR(PIV!J24/PIV!$T24,"")=0,"",IFERROR(PIV!J24/PIV!$T24,"")) -> 0.045602606 | AA55: =IF(IFERROR(PIV!K24/PIV!$T24,"")=0,"",IFERROR(PIV!K24/PIV!$T24,"")) -> 0.074918567 | ... AH55: =IF(IFERROR(PIV!R24/PIV!$T24,"")=0,"",IFERROR(PIV!R24/PIV!$T24,"")) -> 0.027144408
R56: Nov | S56: 1742 | T56: =IF(IFERROR(PIV!D25/PIV!$T25,"")=0,"",IFERROR(PIV!D25/PIV!$T25,"")) | U56: =IF(IFERROR(PIV!E25/PIV!$T25,"")=0,"",IFERROR(PIV!E25/PIV!$T25,"")) | V56: =IF(IFERROR(PIV!F25/PIV!$T25,"")=0,"",IFERROR(PIV!F25/PIV!$T25,"")) | W56: =IF(IFERROR(PIV!G25/PIV!$T25,"")=0,"",IFERROR(PIV!G25/PIV!$T25,"")) | X56: =IF(IFERROR(PIV!H25/PIV!$T25,"")=0,"",IFERROR(PIV!H25/PIV!$T25,"")) | Y56: =IF(IFERROR(PIV!I25/PIV!$T25,"")=0,"",IFERROR(PIV!I25/PIV!$T25,"")) | Z56: =IF(IFERROR(PIV!J25/PIV!$T25,"")=0,"",IFERROR(PIV!J25/PIV!$T25,"")) -> 0.0028702641 | AA56: =IF(IFERROR(PIV!K25/PIV!$T25,"")=0,"",IFERROR(PIV!K25/PIV!$T25,"")) -> 0.082663605 | ... AH56: =IF(IFERROR(PIV!R25/PIV!$T25,"")=0,"",IFERROR(PIV!R25/PIV!$T25,"")) -> 0.022962113
R57: Dec | S57: 2242 | T57: =IF(IFERROR(PIV!D26/PIV!$T26,"")=0,"",IFERROR(PIV!D26/PIV!$T26,"")) | U57: =IF(IFERROR(PIV!E26/PIV!$T26,"")=0,"",IFERROR(PIV!E26/PIV!$T26,"")) | V57: =IF(IFERROR(PIV!F26/PIV!$T26,"")=0,"",IFERROR(PIV!F26/PIV!$T26,"")) | W57: =IF(IFERROR(PIV!G26/PIV!$T26,"")=0,"",IFERROR(PIV!G26/PIV!$T26,"")) | X57: =IF(IFERROR(PIV!H26/PIV!$T26,"")=0,"",IFERROR(PIV!H26/PIV!$T26,"")) | Y57: =IF(IFERROR(PIV!I26/PIV!$T26,"")=0,"",IFERROR(PIV!I26/PIV!$T26,"")) | Z57: =IF(IFERROR(PIV!J26/PIV!$T26,"")=0,"",IFERROR(PIV!J26/PIV!$T26,"")) | AA57: =IF(IFERROR(PIV!K26/PIV!$T26,"")=0,"",IFERROR(PIV!K26/PIV!$T26,"")) -> 0.005352364 | ... AH57: =IF(IFERROR(PIV!R26/PIV!$T26,"")=0,"",IFERROR(PIV!R26/PIV!$T26,"")) -> 0.023639607
Q58: 2026 | R58: Jan | S58: 278 | T58: =IF(IFERROR(PIV!D27/PIV!$T27,"")=0,"",IFERROR(PIV!D27/PIV!$T27,"")) | U58: =IF(IFERROR(PIV!E27/PIV!$T27,"")=0,"",IFERROR(PIV!E27/PIV!$T27,"")) | V58: =IF(IFERROR(PIV!F27/PIV!$T27,"")=0,"",IFERROR(PIV!F27/PIV!$T27,"")) | W58: =IF(IFERROR(PIV!G27/PIV!$T27,"")=0,"",IFERROR(PIV!G27/PIV!$T27,"")) | X58: =IF(IFERROR(PIV!H27/PIV!$T27,"")=0,"",IFERROR(PIV!H27/PIV!$T27,"")) | Y58: =IF(IFERROR(PIV!I27/PIV!$T27,"")=0,"",IFERROR(PIV!I27/PIV!$T27,"")) | Z58: =IF(IFERROR(PIV!J27/PIV!$T27,"")=0,"",IFERROR(PIV!J27/PIV!$T27,"")) | AA58: =IF(IFERROR(PIV!K27/PIV!$T27,"")=0,"",IFERROR(PIV!K27/PIV!$T27,"")) | ... AH58: =IF(IFERROR(PIV!R27/PIV!$T27,"")=0,"",IFERROR(PIV!R27/PIV!$T27,"")) -> 0.16906475
R59: Feb | S59: 786 | T59: =IF(IFERROR(PIV!D28/PIV!$T28,"")=0,"",IFERROR(PIV!D28/PIV!$T28,"")) | U59: =IF(IFERROR(PIV!E28/PIV!$T28,"")=0,"",IFERROR(PIV!E28/PIV!$T28,"")) | V59: =IF(IFERROR(PIV!F28/PIV!$T28,"")=0,"",IFERROR(PIV!F28/PIV!$T28,"")) | W59: =IF(IFERROR(PIV!G28/PIV!$T28,"")=0,"",IFERROR(PIV!G28/PIV!$T28,"")) | X59: =IF(IFERROR(PIV!H28/PIV!$T28,"")=0,"",IFERROR(PIV!H28/PIV!$T28,"")) | Y59: =IF(IFERROR(PIV!I28/PIV!$T28,"")=0,"",IFERROR(PIV!I28/PIV!$T28,"")) | Z59: =IF(IFERROR(PIV!J28/PIV!$T28,"")=0,"",IFERROR(PIV!J28/PIV!$T28,"")) | AA59: =IF(IFERROR(PIV!K28/PIV!$T28,"")=0,"",IFERROR(PIV!K28/PIV!$T28,"")) | ... AH59: =IF(IFERROR(PIV!R28/PIV!$T28,"")=0,"",IFERROR(PIV!R28/PIV!$T28,"")) -> 0.058524173
R60: Mar | S60: 598 | T60: =IF(IFERROR(PIV!D29/PIV!$T29,"")=0,"",IFERROR(PIV!D29/PIV!$T29,"")) | U60: =IF(IFERROR(PIV!E29/PIV!$T29,"")=0,"",IFERROR(PIV!E29/PIV!$T29,"")) | V60: =IF(IFERROR(PIV!F29/PIV!$T29,"")=0,"",IFERROR(PIV!F29/PIV!$T29,"")) | W60: =IF(IFERROR(PIV!G29/PIV!$T29,"")=0,"",IFERROR(PIV!G29/PIV!$T29,"")) | X60: =IF(IFERROR(PIV!H29/PIV!$T29,"")=0,"",IFERROR(PIV!H29/PIV!$T29,"")) | Y60: =IF(IFERROR(PIV!I29/PIV!$T29,"")=0,"",IFERROR(PIV!I29/PIV!$T29,"")) | Z60: =IF(IFERROR(PIV!J29/PIV!$T29,"")=0,"",IFERROR(PIV!J29/PIV!$T29,"")) | AA60: =IF(IFERROR(PIV!K29/PIV!$T29,"")=0,"",IFERROR(PIV!K29/PIV!$T29,"")) | ... AH60: =IF(IFERROR(PIV!R29/PIV!$T29,"")=0,"",IFERROR(PIV!R29/PIV!$T29,"")) -> 0.016722408
R61: Apr | S61: 733 | T61: =IF(IFERROR(PIV!D30/PIV!$T30,"")=0,"",IFERROR(PIV!D30/PIV!$T30,"")) | U61: =IF(IFERROR(PIV!E30/PIV!$T30,"")=0,"",IFERROR(PIV!E30/PIV!$T30,"")) | V61: =IF(IFERROR(PIV!F30/PIV!$T30,"")=0,"",IFERROR(PIV!F30/PIV!$T30,"")) | W61: =IF(IFERROR(PIV!G30/PIV!$T30,"")=0,"",IFERROR(PIV!G30/PIV!$T30,"")) | X61: =IF(IFERROR(PIV!H30/PIV!$T30,"")=0,"",IFERROR(PIV!H30/PIV!$T30,"")) | Y61: =IF(IFERROR(PIV!I30/PIV!$T30,"")=0,"",IFERROR(PIV!I30/PIV!$T30,"")) | Z61: =IF(IFERROR(PIV!J30/PIV!$T30,"")=0,"",IFERROR(PIV!J30/PIV!$T30,"")) | AA61: =IF(IFERROR(PIV!K30/PIV!$T30,"")=0,"",IFERROR(PIV!K30/PIV!$T30,"")) | ... AH61: =IF(IFERROR(PIV!R30/PIV!$T30,"")=0,"",IFERROR(PIV!R30/PIV!$T30,"")) -> 0.017735334

Sheet Delivered MC
A1: Delviered Date | B1: Delivered Year | C1: Delivered Month | D1: Delivered RMA Count
A2: =DATE(B2,MONTH(1&C2),1) -> 45778 | B2: 2025 | C2: May | D2: 138
A3: =DATE(B3,MONTH(1&C3),1) -> 45809 | B3: 2025 | C3: Jun | D3: 1004
A4: =DATE(B4,MONTH(1&C4),1) -> 45839 | B4: 2025 | C4: Jul | D4: 1081
A5: =DATE(B5,MONTH(1&C5),1) -> 45870 | B5: 2025 | C5: Aug | D5: 956
A6: =DATE(B6,MONTH(1&C6),1) -> 45901 | B6: 2025 | C6: Sep | D6: 840
A7: =DATE(B7,MONTH(1&C7),1) -> 45931 | B7: 2025 | C7: Oct | D7: 921
A8: =DATE(B8,MONTH(1&C8),1) -> 45962 | B8: 2025 | C8: Nov | D8: 1742
A9: =DATE(B9,MONTH(1&C9),1) -> 45992 | B9: 2025 | C9: Dec | D9: 2242
A10: =DATE(B10,MONTH(1&C10),1) -> 46023 | B10: 2026 | C10: Jan | D10: 278
A11: =DATE(B11,MONTH(1&C11),1) -> 46054 | B11: 2026 | C11: Feb | D11: 786
A12: =DATE(B12,MONTH(1&C12),1) -> 46082 | B12: 2026 | C12: Mar | D12: 598
A13: =DATE(B13,MONTH(1&C13),1) -> 46113 | B13: 2026 | C13: Apr | D13: 733
... A21: =DATE(B21,MONTH(1&C21),1) -> 46357 | B21: 2026 | C21: Dec | D21: 0

Sheet Odoo_Combined
A1: Issue Reported Date | B1: Customer's Name | C1: Order# | D1: MachineSerialNumber | E1: Replacement Type | F1: Roti Count | G1: Return Type | H1: Replacement SO | I1: Request Month | J1: Year | K1: Failure.Keyword | L1: Failure.Failure Mode | M1: Failure.Failure Category | N1: Shipment Month | O1: Shipped Year | P1: CA/ME | Q1: WW Code | R1: MC Type | S1: RMA Lines | T1: Status | U1: Fee Amount | V1: Is Shipment Initiated | W1: SO Return Status | X1: Roti Count Group
A2: 46237 | B2: Sujith Vijaya Kumar | C2: 74081 | D2: ZM1251250CAW06644 | E2: Machine | F2: 875 | G2: Replacement | H2: RSO09356 | I2: Aug | J2: 2026 | K2: KNEADING TRAY STUCK | L2: Kneader Stuck | M2: Kneader | N2: Dec | O2: 2025 | P2: CA | Q2: 50 | R2: RNext | S2: [ZNF0111AW-CA] Rotimatic Next (Black & White) | T2: Processing | U2: 40 | V2: 1 | W2: Return with Refund/Replacement | X2: 500–999
A3: 46237 | B3: Shalaka Sawant | C3: 75980 | D3: ZM1251251CAG07710 | E3: Machine | F3: 116 | G3: Replacement | H3: RSO09355 | I3: Aug | J3: 2026 | K3: TRANSFER ARM RATTLING NOISE | L3: Kicker Noise | M3: Kicker Module | N3: Dec | O3: 2025 | P3: CA | Q3: 51 | R3: RNext | S3: [ZNF0111AG-CA] Rotimatic Next (Black & Grey) | T3: Processing | U3: 0 | V3: 1 | W3: Return with Refund/Replacement | X3: 50–499
A4: 46237 | B4: Neel Shah | C4: RSO03202 | D4: ZM1250729CAG01563 | E4: Machine | F4: 0 | G4: Replacement | H4: RSO09354 | I4: Aug | J4: 2026 | K4: KNEADER BLADE STUCK | L4: Kneader Blade Stuck | M4: Kneader | N4: Jul | O4: 2025 | P4: CA | Q4: 29 | R4: RNext | S4: [ZNF0111AG-CA] Rotimatic Next (Black & Grey) | T4: Processing | U4: 0 | V4: 1 | W4: Return with Refund/Replacement | X4: 0–49
A5: 46237 | B5: Owais Ahmed | C5: RSO05154 | D5: ZM1251146MEG01650 | E5: Machine | F5: 963 | G5: Replacement | H5: RSO09353 | I5: Aug | J5: 2026 | K5: CANNOT TRANSFER DOUGH BALL | L5: Kicker Drive | M5: Kicker Module | N5: Nov | O5: 2025 | P5: ME | Q5: 46 | R5: RNext | S5: [ZNF0111AG-ME] Rotimatic Next (Black & Grey) | T5: Processing | U5: 0 | V5: 1 | W5: Return with Refund/Replacement | X5: 500–999
A6: 46237 | B6: Saurabh Brahmbhatt | C6: 41090 | D6: ZM82308CAB139 | E6: Machine | F6: 8500 | G6: Replacement | H6: RSO09352 | I6: Aug | J6: 2026 | N6: Aug | O6: 2023 | P6: B1 | Q6: CA | R6: RPlus | S6: [ZMA0111A-CA] Rotimatic Plus | T6: Processing | U6: 0 | V6: 1 | W6: Return with Refund/Replacement | X6: 5,000+
A7: 46237 | B7: Pranjal Jain | C7: RSO04838 | D7: ZM1251144CAW04488 | E7: Machine | F7: 609 | G7: Replacement | H7: RSO09351 | I7: Aug | J7: 2026 | K7: NOT POWERING ON | L7: Not Powering On | M7: Electrical | N7: Nov | O7: 2025 | P7: CA | Q7: 44 | R7: RNext | S7: [ZNF0111AW-CA] Rotimatic Next (Black & White) | T7: Processing | U7: 0 | V7: 1 | W7: Return with Refund/Replacement | X7: 500–999
A8: 46234 | B8: Ashish Mehta | C8: 78106 | D8: ZM1260102CAG08113 | E8: Machine | F8: 433 | G8: Replacement | H8: RSO09350 | I8: Jul | J8: 2026 | K8: NOT POWERING ON | L8: Not Powering On | M8: Electrical | N8: Jan | O8: 2026 | P8: CA | Q8: 02 | R8: RNext | S8: [ZNF0111AG-CA] Rotimatic Next (Black & Grey) | T8: Processing | U8: 0 | V8: 1 | W8: Return with Refund/Replacement | X8: 50–499
A9: 46234 | B9: Rohit Yadav | C9: 62977 | D9: ZM1250416CAG00186 | E9: Machine | F9: 712 | G9: Replacement | H9: RSO09349 | I9: Jul | J9: 2026 | K9: TRANSFER ARM STUCK | L9: Kicker Drive | M9: Kicker Module | N9: Apr | O9: 2025 | P9: CA | Q9: 16 | R9: RNext | S9: [ZMA0111A-CA] Rotimatic Plus | T9: Processing | U9: 0 | V9: 1 | W9: Return with Refund/Replacement | X9: 500–999
A10: 46234 | B10: Brigade People Pty Ltd | C10: 68935 | D10: ZM1250835MEW00868 | E10: Machine | F10: 0 | G10: Replacement | H10: RSO09348 | I10: Jul | J10: 2026 | K10: KNEADER BLADE STUCK | L10: Kneader Blade Stuck | M10: Kneader | N10: Aug | O10: 2025 | P10: ME | Q10: 35 | R10: RNext | S10: [ZNF0111AW-ME] Rotimatic Next (Black & White) | T10: Processing | U10: 172 | V10: 1 | W10: Return with Refund/Replacement | X10: 0–49
A11: 46234 | B11: sateesh vadde | C11: 71143 | D11: ZM1251043CAG03935 | E11: Machine | F11: 0 | G11: Replacement | H11: RSO09347 | I11: Jul | J11: 2026 | K11: TRANSFER ARM STUCK | L11: Kicker Drive | M11: Kicker Module | N11: Oct | O11: 2025 | P11: CA | Q11: 43 | R11: RNext | S11: [ZNF0111AG-CA] Rotimatic Next (Black & Grey) | T11: Processing | U11: 211 | V11: 1 | W11: Return with Refund/Replacement | X11: 0–49
A12: 46234 | B12: Ashleye Soanes | C12: 80569 | D12: ZM1260311CAW09995 | E12: Machine | F12: 0 | G12: Replacement | H12: RSO09346 | I12: Jul | J12: 2026 | K12: TRANSFER ARM STUCK | L12: Kicker Drive | M12: Kicker Module | N12: Mar | O12: 2026 | P12: CA | Q12: 11 | R12: RNext | S12: [ZNF0111AW-CA] Rotimatic Next (Black & White) | T12: Processing | U12: 54 | V12: 1 | W12: Return with Refund/Replacement | X12: 0–49
A13: 46234 | B13: varun_varmani@hotmail.com | C13: 76496 | D13: ZM1260209MEG03101 | E13: Machine | F13: 0 | G13: Replacement | H13: RSO09345 | I13: Jul | J13: 2026 | K13: TRANSFER ARM STUCK | L13: Kicker Drive | M13: Kicker Module | N13: Feb | O13: 2026 | P13: ME | Q13: 09 | R13: RNext | S13: [2YearRotimaticNextRotimaticCareWarranty] Rotimatic Next - Rotimatic Care Plus Warranty - 2 Years | T13: Processing | U13: 125 | V13: 1 | W13: Return with Refund/Replacement | X13: 0–49
A14: 46234 | B14: Rajesh Ganta | C14: 80144 | D14: ZM1260208CAG09747 | E14: Machine | F14: 0 | G14: Replacement | H14: RSO09344 | I14: Jul | J14: 2026 | K14: NOT POWERING ON | L14: Not Powering On | M14: Electrical | N14: Feb | O14: 2026 | P14: CA | Q14: 08 | R14: RNext | S14: [ZNF0111AG-CA] Rotimatic Next (Black & Grey) | T14: Processing | U14: 40 | V14: 1 | W14: Return with Refund/Replacement | X14: 0–49
A15: 46234 | B15: Pratik Pradhan | C15: 77473 | D15: ZM1260209MEG02955 | E15: Machine | F15: 0 | G15: Replacement | H15: RSO09343 | I15: Jul | J15: 2026 | K15: RATTLING NOISE | L15: Rattling Noise | M15: Kicker Module | N15: Feb | O15: 2026 | P15: ME | Q15: 09 | R15: RNext | S15: [ZNF0111AG-ME] Rotimatic Next (Black & Grey) | T15: Processing | U15: 0 | V15: 1 | W15: Return with Refund/Replacement | X15: 0–49
A16: 46234 | B16: Ashwanth Sivankutty Nair | C16: 69496 | D16: ZM1250836CAG02766 | E16: Machine | F16: 0 | G16: Replacement | H16: RSO09342 | I16: Jul | J16: 2026 | N16: Aug | O16: 2025 | P16: CA | Q16: 36 | R16: RNext | S16: [1YearRotimaticNextRotimaticCareWarranty] Rotimatic Next - Rotimatic Care Plus Warranty - 1 Year | T16: Processing | U16: 41 | V16: 1 | W16: Return with Refund/Replacement | X16: 0–49
A17: 46234 | B17: Sunmeet Singh | C17: RSO05345 | D17: ZM1251146MEG01682 | E17: Machine | F17: 0 | G17: Replacement | H17: RSO09341 | I17: Jul | J17: 2026 | K17: PRESS PAN STUCK | L17: Press Pan Malfunction | M17: Press Pan Module | N17: Nov | O17: 2025 | P17: ME | Q17: 46 | R17: RNext | S17: [ZNF0111AG-ME] Rotimatic Next (Black & Grey) | T17: Processing | U17: 0 | V17: 1 | W17: Return with Refund/Replacement | X17: 0–49
A18: 46234 | B18: Sunita Khara | C18: 78487 | D18: ZM1260209CAW09903 | E18: Machine | F18: 0 | G18: Replacement | H18: RSO09340 | I18: Jul | J18: 2026 | K18: NOT POWERING ON | L18: Not Powering On | M18: Electrical | N18: Feb | O18: 2026 | P18: CA | Q18: 09 | R18: RNext | S18: [ZNF0111AW-CA] Rotimatic Next (Black & White) | T18: Processing | U18: 40 | V18: 1 | W18: Return with Refund/Replacement | X18: 0–49
A19: 46234 | B19: Munish Minocha | C19: 79729 | D19: ZM1260311CAW09988 | E19: Machine | F19: 0 | G19: Replacement | H19: RSO09339 | I19: Jul | J19: 2026 | K19: NOT POWERING ON | L19: Not Powering On | M19: Electrical | N19: Mar | O19: 2026 | P19: CA | Q19: 11 | R19: RNext | S19: [ZNF0111AW-CA] Rotimatic Next (Black & White) | T19: Processing | U19: 48 | V19: 1 | W19: Return with Refund/Replacement | X19: 0–49
A20: 46233 | B20: vidhi modi | C20: 70306 | D20: ZM1251043CAG03932 | G20: Refund with Return | I20: Jul | J20: 2026 | K20: NOT POWERING ON | L20: Not Powering On | M20: Electrical | N20: Oct | O20: 2025 | P20: CA | Q20: 43 | R20: RNext | S20: [6MonthsRotimaticNextRotimaticCareWarranty] Rotimatic Next - Rotimatic Care Plus Warranty - 6 Months | T20: Submitted | U20: 0 | V20: 1 | W20: Cancellation
A21: 46233 | B21: Sayali Autade | C21: 74763 | D21: ZM1251250CAW06779 | E21: Machine | F21: 1914 | G21: Replacement | H21: RSO09338 | I21: Jul | J21: 2026 | K21: KNEADING TRAY STUCK | L21: Kneader Stuck | M21: Kneader | N21: Dec | O21: 2025 | P21: CA | Q21: 50 | R21: RNext | S21: [2YearRotimaticNextRotimaticCareWarranty] Rotimatic Next - Rotimatic Care Plus Warranty - 2 Years | T21: Processing | U21: 40 | V21: 1 | W21: Return with Refund/Replacement | X21: 1,000–1,999
A22: 46233 | B22: Alakh Biniwale | C22: 71777 | D22: ZM1251146CAG04887 | E22: Machine | F22: 0 | G22: Replacement | H22: RSO09337 | I22: Jul | J22: 2026 | K22: TOP CASING CRACK | L22: Cracked Machine | M22: Logistics | N22: Nov | O22: 2025 | P22: CA | Q22: 46 | R22: RNext | S22: [3YearRotimaticNextRotimaticCareWarranty] Rotimatic Next - Rotimatic Care Plus Warranty - 3 Years | T22: Processing | U22: 63 | V22: 1 | W22: Return with Refund/Replacement | X22: 0–49
A23: 46233 | B23: Anmol Singh | C23: RSO04577 | D23: ZM1250940CAW03285 | E23: Machine | F23: 0 | G23: Replacement | H23: RSO09336 | I23: Jul | J23: 2026 | K23: NOT POWERING ON | L23: Not Powering On | M23: Electrical | N23: Sep | O23: 2025 | P23: CA | Q23: 40 | R23: RNext | S23: [ZNF0111AG-CA] Rotimatic Next (Black & Grey) | T23: Processing | U23: 0 | V23: 1 | W23: Return with Refund/Replacement | X23: 0–49
A24: 46232 | B24: Shipra Singh | C24: RSO05912 | D24: ZM1251250CAW06647 | E24: Machine | F24: 48 | G24: Replacement | H24: RSO09335 | I24: Jul | J24: 2026 | N24: Dec | O24: 2025 | P24: CA | Q24: 50 | R24: RNext | S24: [ZNF0111AW-CA] Rotimatic Next (Black & White) | T24: Processing | U24: 0 | V24: 1 | W24: Return with Refund/Replacement | X24: 0–49
A25: 46232 | B25: Ajay Sekhri | C25: 64218 | D25: ZM1250626CAW01396 | E25: Machine | F25: 230 | G25: Replacement | H25: RSO09334 | I25: Jul | J25: 2026 | K25: KNEADING TRAY STUCK | L25: Kneader Stuck | M25: Kneader | N25: Jun | O25: 2025 | P25: CA | Q25: 26 | R25: RNext | S25: [3YearRotimaticNextRotimaticCareWarranty] Rotimatic Next - Rotimatic Care Plus Warranty - 3 Years | T25: Processing | U25: 0 | V25: 1 | W25: Return with Refund/Replacement | X25: 50–499
A26: 46232 | B26: Abhishek Dhoundiyal | C26: RSO08422 | D26: ZM1260417CAG10464 | E26: Machine | F26: 305 | G26: Replacement | H26: RSO09333 | I26: Jul | J26: 2026 | K26: TRANSFER ARM RATTLING NOISE | L26: Kicker Noise | M26: Kicker Module | N26: Apr | O26: 2026 | P26: CA | Q26: 17 | R26: RNext | S26: [ZNF0111AG-CA] Rotimatic Next (Black & Grey) | T26: Processing | U26: 0 | V26: 1 | W26: Return with Refund/Replacement | X26: 50–499
A27: 46231 | B27: Shekar datt maharaj | C27: 81420 | D27: ZM1251250MEG02403 | F27: 128 | G27: Refund with Return | I27: Jul | J27: 2026 | K27: TRANSFER ARM STUCK | L27: Kicker Drive | M27: Kicker Module | N27: Dec | O27: 2025 | P27: ME | Q27: 50 | R27: RNext | S27: [ZNF0111AG-ME] Rotimatic Next (Black & Grey) | T27: Submitted | U27: 65 | V27: 1 | W27: Cancellation | X27: 50–499
A28: 46231 | B28: Rahiman Mohammad | C28: 69178 | D28: ZM1250835CAG02569 | E28: Machine | F28: 1638 | G28: Replacement | H28: RSO09332 | I28: Jul | J28: 2026 | K28: KNEADER BLADE STUCK | L28: Kneader Blade Stuck | M28: Kneader | N28: Aug | O28: 2025 | P28: CA | Q28: 35 | R28: RNext | S28: [ZNF0111AG-CA] Rotimatic Next (Black & Grey) | T28: Processing | U28: 197 | V28: 1 | W28: Return with Refund/Replacement | X28: 1,000–1,999
A29: 46231 | B29: Suchithra Gopinath | C29: 71894 | D29: ZM1251144CAG04882 | E29: Part | F29: 1042 | G29: Replacement | H29: RSO09331 | I29: Jul | J29: 2026 | K29: DAMAGED KICKER | L29: Kicker Catcher Issue | M29: Kicker Module | N29: Nov | O29: 2025 | P29: CA | Q29: 44 | R29: RNext | S29: [2YearRotimaticNextRotimaticCareWarranty] Rotimatic Next - Rotimatic Care Plus Warranty - 2 Years | T29: Closed | U29: 43 | V29: 1 | W29: Return with Refund/Replacement | X29: 1,000–1,999
A30: 46231 | B30: Vijay Subramanyam | C30: 76268 | D30: ZM1251251CAG07726 | F30: 2 | G30: Refund with Return | I30: Jul | J30: 2026 | K30: LEAKAGE | L30: Leakage | M30: Ingredient System | N30: Dec | O30: 2025 | P30: CA | Q30: 51 | R30: RNext | S30: [ZNF0111AG-CA] Rotimatic Next (Black & Grey) | T30: Submitted | U30: 35 | V30: 1 | W30: Cancellation | X30: 0–49
A31: 46231 | B31: ILango Marag | C31: 74743 | D31: ZM1251251CAG07419 | E31: Machine | F31: 756 | G31: Replacement | H31: RSO09330 | I31: Jul | J31: 2026 | K31: TRANSFER ARM RATTLING NOISE | L31: Kicker Noise | M31: Kicker Module | N31: Dec | O31: 2025 | P31: CA | Q31: 51 | R31: RNext | S31: [ZNF0111AG-CA] Rotimatic Next (Black & Grey) | T31: Processing | U31: 0 | V31: 1 | W31: Return with Refund/Replacement | X31: 500–999
A32: 46231 | B32: Chetan Pachchhao | C32: RSO06651 | D32: ZM1260208CAG09764 | E32: Machine | F32: 298 | G32: Replacement | H32: RSO09329 | I32: Jul | J32: 2026 | N32: Feb | O32: 2026 | P32: CA | Q32: 08 | R32: RNext | S32: [ZNF0111AG-CA] Rotimatic Next (Black & Grey) | T32: Processing | U32: 0 | V32: 1 | W32: Return with Refund/Replacement | X32: 50–499
A33: 46231 | B33: Ritika Kureti | C33: RSO02801 | D33: ZM1250415CAG00126 | E33: Machine | F33: 0 | G33: Replacement | H33: RSO09328 | I33: Jul | J33: 2026 | N33: Apr | O33: 2025 | P33: CA | Q33: 15 | R33: RNext | S33: [ZNF0111AG-CA] Rotimatic Next (Black & Grey) | T33: Processing | U33: 0 | V33: 1 | W33: Return with Refund/Replacement | X33: 0–49
A34: 46230 | B34: Sana Chaudhry | C34: 72664 | D34: ZM1251146CAG05219 | E34: Machine | F34: 667 | G34: Replacement | H34: RSO09308 | I34: Jul | J34: 2026 | K34: NOT POWERING ON | L34: Not Powering On | M34: Electrical | N34: Nov | O34: 2025 | P34: CA | Q34: 46 | R34: RNext | S34: [ZNF0111AG-CA] Rotimatic Next (Black & Grey) | T34: Processing | U34: 0 | V34: 1 | W34: Return with Refund/Replacement | X34: 500–999
A35: 46230 | B35: Zebra Khan | C35: 68800 | D35: ZM1251042MEW01583 | E35: Machine | F35: 0 | G35: Replacement | H35: RSO09299 | I35: Jul | J35: 2026 | K35: TRANSFER ARM STUCK | L35: Kicker Drive | M35: Kicker Module | N35: Oct | O35: 2025 | P35: ME | Q35: 42 | R35: RNext | S35: [3YearRotimaticNextRotimaticCareWarranty] Rotimatic Next - Rotimatic Care Plus Warranty - 3 Years | T35: Processing | U35: 153 | V35: 1 | W35: Return with Refund/Replacement | X35: 0–49
A36: 46230 | B36: Nikita Pawar | C36: 78099 | D36: ZM1260311MEG03178 | E36: Machine | F36: 43 | G36: Replacement | H36: RSO09327 | I36: Jul | J36: 2026 | K36: DAMAGED PART INSIDE THE MACHINE | L36: Damaged Component | M36: Assembly/Packaging | N36: Mar | O36: 2026 | P36: ME | Q36: 11 | R36: RNext | S36: [3YearRotimaticNextRotimaticCareWarranty] Rotimatic Next - Rotimatic Care Plus Warranty - 3 Years | T36: Processing | U36: 0 | V36: 1 | W36: Return with Refund/Replacement | X36: 0–49
A37: 46230 | B37: Shambhavi Mohan | C37: 55085 | D37: ZM82405CAB00E | E37: Machine | F37: 2934 | G37: Replacement | H37: RSO09326 | I37: Jul | J37: 2026 | K37: FINAL CHECK STAGE AND DOES NOT PROCEED FURTHER | L37: Final Check Stage Stuck | M37: Others | N37: May | O37: 2024 | P37: B0 | Q37: CA | R37: RPlus | S37: [Extend-Protection-Plan-299.00] Extend Protection Plan - US - 2 Years (299.00) | T37: Processing | U37: 40 | V37: 1 | W37: Return with Refund/Replacement | X37: 2,000–2,999
A38: 46230 | B38: Tarun Kalyani | C38: 67400 | D38: ZM1250940MEG01005 | E38: Part | F38: 523 | G38: Replacement | H38: RSO09325 | I38: Jul | J38: 2026 | K38: DAMAGED KICKER | L38: Kicker Catcher Issue | M38: Kicker Module | N38: Sep | O38: 2025 | P38: ME | Q38: 40 | R38: RNext | S38: [ZNF0111AG-ME] Rotimatic Next (Black & Grey) | T38: Closed | U38: 0 | V38: 1 | W38: Return with Refund/Replacement | X38: 500–999
A39: 46230 | B39: Pavan Reddy | C39: 69167 | D39: ZM125940MEG00998 | E39: Machine | F39: 0 | G39: Replacement | H39: RSO09324 | I39: Jul | J39: 2026 | K39: CANNOT TRANSFER DOUGH BALL | L39: Kicker Drive | M39: Kicker Module | O39: 2025 | P39: EG | Q39: 0M | R39: RNext | S39: [ZNF0111AG-ME] Rotimatic Next (Black & Grey) | T39: Processing | U39: 0 | V39: 1 | W39: Return with Refund/Replacement | X39: 0–49
A40: 46230 | B40: Manoj Deshpande | C40: 72199 | D40: ZM1251146CAW5311 | E40: Machine | F40: 780 | G40: Replacement | H40: RSO09323 | I40: Jul | J40: 2026 | K40: KNEADER TRAY STUCK | L40: Kneader Stuck | M40: Kneader | N40: Nov | O40: 2025 | P40: CA | Q40: 46 | R40: RNext | S40: [2YearRotimaticNextRotimaticCareWarranty] Rotimatic Next - Rotimatic Care Plus Warranty - 2 Years | T40: Processing | U40: 46 | V40: 1 | W40: Return with Refund/Replacement | X40: 500–999
...

Sheet Field RMA
A1: Issue Reported Date | B1: Customer's Name | C1: Order# | D1: MachineSerialNumber | E1: Return Type | F1: Roti Count | G1: Notes_Clean
A2: 46225 | B2: Robin Chandil | C2: 78583 | D2: ZM1260417CAW10378 | E2: Replacement | F2: 352 | G2: VT STUCK
A3: 46225 | B3: Achal Dave | C3: 79532 | D3: ZM1260209MEG02947 | E3: Replacement | F3: 163 | G3: KNEADER TRAY STUCK
A4: 46225 | B4: Akhil Reddy Sabhapathi | C4: 65327 | D4: ZM1250729CAG01659 | E4: Replacement | F4: 13 | G4: TRANSFER ARM RATTLING NOISE
A5: 46225 | B5: Sarthak Arora | C5: 73058 | D5: ZM1251147CAG05568 | E5: Replacement | F5: 29 | G5: FLOUR SPILLAGE
A6: 46225 | B6: Prathamesh Thakur | C6: 66415 | D6: ZM1250835MEG00900 | E6: Replacement | F6: 394 | G6: TRANSFER ARM STUCK
A7: 46225 | B7: LEKHRAJ PATEL | C7: 82057 | D7: ZM1260311CAW09973 | E7: Replacement | F7: 182 | G7: TRANSFER ARM RATTLING NOISE
A8: 46225 | B8: Ashwini Metkar | C8: RSO02723 | D8: ZM1250835CAG02550 | E8: Replacement | F8: 314 | G8: TOP CASING CRACK
A9: 46225 | B9: Rushikesh Veni | C9: RSO03479 | D9: ZM1250728CAG01460 | E9: Replacement | F9: 1613 | G9: KNEADER TRAY STUCK
A10: 46225 | B10: Vikrant Yagnick | C10: RSO04349 | D10: ZM1250939CAW03194 | E10: Replacement | F10: 1000 | G10: BROKEN KICKER RAIL
A11: 46225 | B11: Rhythm Varshney | C11: 66755 | D11: ZM1250729CAG01651 | E11: Replacement | F11: 1466 | G11: TRANSFER ARM RATTLING NOISE
A12: 46225 | B12: Rahul Arke | C12: 64335 | D12: ZM1250625CAG00938 | E12: Replacement | F12: 1803 | G12: KNEADER TRAY STUCK
A13: 46225 | B13: Rajeev Kumar | C13: 72057 | D13: ZM1251147CAG05608 | E13: Replacement | F13: 1725 | G13: CANNOT TRANSFER DOUGHBALL
A14: 46224 | B14: Shambhavi Mohan | C14: 55085 | D14: ZM82405CAB00E | E14: Replacement | F14: 2934 | G14: MACHINE FAILURE
A15: 46223 | B15: Jayaprakash Rajendran | C15: 49968 | D15: ZM1260206MEG02650 | F15: 196 | G15: UNABLE TO USE MILLER UPDATE
A16: 46220 | B16: Vishnu Sreekumar | C16: 63119 | D16: ZM1250626CAW01331 | F16: 386 | G16: NOT POWERING ON
A17: 46220 | B17: Dipesh Malik | C17: 69886 | D17: ZM1251249MEG02117 | E17: Replacement | F17: 20 | G17: STIRRER NOT ROTATING
A18: 46219 | B18: Dines Kumar Kesa | C18: 68894 | D18: ZM1250937CAG02883 | E18: Replacement | F18: 311 | G18: KNEAD BLADE STUCK
A19: 46219 | B19: Bhajneek Bajwa | C19: RSO05458 | D19: ZM1251147CAG05389 | E19: Replacement | F19: 1305 | G19: APPROVED BY PARUL
A20: 46219 | B20: VIVEK CHITTAMURI | C20: 76575 | D20: ZM1251251CAG07874 | E20: Replacement | F20: 1028 | G20: TRANSFER ARM RATTLING NOISE
A21: 46219 | B21: Amit kumar | C21: 71946 | D21: ZM1251041MEG01314 | F21: 831 | G21: DAMAGED KICKER
A22: 46219 | B22: Prakash Gudsoorkar | C22: 63988 | D22: ZM1250834CAG02539 | F22: 988 | G22: PANS NOT HEATING
A23: 46219 | B23: Mansoor Wani | C23: 67495 | D23: ZM1251249MEG01965 | F23: 0 | G23: LOAD CELL ISSUE
A24: 46218 | B24: Sharad Kumar Sangal | C24: 79171 | D24: ZM1260417CAG10142 | E24: Parts Replacement | F24: 362 | G24: DAMAGED KICKER
A25: 46218 | B25: Shubhanshu Verma | C25: 72393 | D25: ZM1251251CAG07860 | E25: Parts Replacement | F25: 154 | G25: DAMAGED STIRRER
A26: 46218 | B26: Jaydeep Taralkar | C26: 71712 | D26: ZM1251249CAW06239 | E26: Parts Replacement | F26: 26 | G26: DAMAGED KICKER
A27: 46218 | B27: Ritvika Sharma | C27: 75442 | D27: ZM1251251CAG07209 | E27: Parts Replacement | F27: 917 | G27: DAMAGED KICKER
A28: 46218 | B28: Desh Deepak | C28: 75509 | D28: ZM1251147CAW05762 | G28: NA
A29: 46217 | B29: Simar Jaggi | C29: 67652 | D29: ZM1250937CAG02886 | E29: Parts Replacement | F29: 583 | G29: DAMAGED KICKER
A30: 46217 | B30: Deepika Udhani | C30: 48844 | D30: ZM82402MEB023 | E30: Replacement | G30: OIL LEAKAGE
A31: 46217 | B31: Shobana Subramani | C31: 74158 | D31: ZM1260102CAG08281 | E31: Parts Replacement | F31: 32 | G31: DAMAGED KICKER
A32: 46217 | B32: Darakshan Anwar | C32: 74473 | D32: ZM1260104CAW09076 | E32: Parts Replacement | F32: 0 | G32: DAMAGED KICKER
A33: 46217 | B33: Harita Dave | C33: 73105 | D33: ZM1251251CAG07899 | E33: Parts Replacement | F33: 849 | G33: DAMAGED KICKER
A34: 46217 | B34: Nirav Ginwala | C34: 63441 | D34: ZM1250836CAG02739 | E34: Parts Replacement | F34: 1235 | G34: DAMAGED KICKER
A35: 46217 | B35: Damini Desai | C35: 68632 | D35: ZM1251147CAG05421 | G35: CANNOT TRANSFER DOUGHBALL
A36: 46216 | B36: Shirish Chandrashekhar Jambhorkar | C36: 72298 | D36: ZM1251042MEW01573 | G36: KICKER RAIL UNPARALLEL
A37: 46216 | B37: Hardik Shah | C37: 63651 | D37: ZM1250626CAW01336 | E37: Replacement | F37: 593 | G37: LOUD KNEADING NOISE
A38: 46216 | B38: Hemant Phadnis | C38: 75945 | D38: ZM1260104CAW08975 | E38: Replacement | G38: CANNOT DISPENSE WATER
A39: 46216 | B39: somdeb chatterjee | C39: 64684 | D39: ZM1250730CAW01944 | E39: Parts Replacement | F39: 753 | G39: DAMAGED KICKER
A40: 46216 | B40: Bhavesh Bhandarker | C40: 78568 | D40: ZM1260311MEG03266 | E40: Replacement | F40: 0 | G40: CANNOT CONNECT TO WI-FI
...

Sheet FailureMapping
A1: Keyword | B1: Failure Mode | C1: Failure Category
A2: AESTHETICS | B2: Cosmetic Issue | C2: Others
A3: MACHINE NEVER WORKED OUT OF THE BOX | B3: DOA / Out of Box Failure | C3: Others
A4: FINAL CHECK STAGE AND DOES NOT PROCEED FURTHER | B4: Final Check Stage Stuck | C4: Others
A5: FIRMWARE AND HARDWARE ISSUE | B5: Firmware/Hardware Failure | C5: Others
A6: MACHINE STOPPED AFTER MAKING 1 ROTI | B6: Machine Performance Issue | C6: Others
A7: MACHINE PERFORMANCE | B7: Machine Performance Issue | C7: Others
A8: CLEANING BRUSH SHREDDING | B8: Cleaning Brush Damage | C8: Accessories
A9: SHREDDING BRUSH | B9: Cleaning Brush Damaged | C9: Accessories
A10: CLEANING BRUSH TO BE REPLACED | B10: Cleaning Brush Damaged | C10: Accessories
A11: APPROVED BY PARUL | B11: Approved by Support | C11: Administrative
A12: CHECKED AND APPROVED BY ENGINEERS | B12: Administrative Note | C12: Administrative
... A680: DB WEIGHT DETECTION WARNING | B680: DB Detection Warning | C680: VT Module

Sheet Odoo
A1: Issue Reported Date | B1: Customer's Name | C1: Order# | D1: MachineSerialNumber | E1: Replacement Type | F1: Roti Count | G1: Return Type | H1: Replacement SO | I1: Status | J1: RMA Lines | K1: Fee Amount | L1: Is Shipment Initiated | M1: SO Return Status | N1: Notes | O1: Notes_Clean
A2: 46237 | B2: Sujith Vijaya Kumar | C2: 74081 | D2: ZM1251250CAW06644 | E2: Machine | F2: 875 | G2: Replacement | H2: RSO09356 | I2: Processing | J2: [ZNF0111AW-CA] Rotimatic Next (Black & White) | K2: 39.807884 | L2: 1 | M2: Return with Refund/Replacement | N2: ZM1251250CAW06644 roti count: 875 Kneading Tray Stuck issue | O2: ZM1251250CAW06644 ROTI COUNT:: 875 KNEADING TRAY STUCK ISSUE
A3: 46237 | B3: Shalaka Sawant | C3: 75980 | D3: ZM1251251CAG07710 | E3: Machine | F3: 116 | G3: Replacement | H3: RSO09355 | I3: Processing | J3: [ZNF0111AG-CA] Rotimatic Next (Black & Grey) | K3: 0 | L3: 1 | M3: Return with Refund/Replacement | N3: ZM1251251CAG07710 roti count: 116 Transfer Arm rattling noise issue | O3: ZM1251251CAG07710 ROTI COUNT:: 116 TRANSFER ARM RATTLING NOISE ISSUE
A4: 46237 | B4: Neel Shah | C4: RSO03202 | D4: ZM1250729CAG01563 | E4: Machine | F4: 0 | G4: Replacement | H4: RSO09354 | I4: Processing | J4: [ZNF0111AG-CA] Rotimatic Next (Black & Grey) | K4: 0 | L4: 1 | M4: Return with Refund/Replacement | N4: ZM1250729CAG01563 roti count: 0 Knead Blade Stuck | O4: ZM1250729CAG01563 ROTI COUNT:: 0 KNEADER BLADE STUCK
A5: 46237 | B5: Owais Ahmed | C5: RSO05154 | D5: ZM1251146MEG01650 | E5: Machine | F5: 963 | G5: Replacement | H5: RSO09353 | I5: Processing | J5: [ZNF0111AG-ME] Rotimatic Next (Black & Grey) | K5: 0 | L5: 1 | M5: Return with Refund/Replacement | N5: ZM1251146MEG01650 roti count: 963 Cannot Transfer Doughball | O5: ZM1251146MEG01650 ROTI COUNT:: 963 CANNOT TRANSFER DOUGH BALL
A6: 46237 | B6: Saurabh Brahmbhatt | C6: 41090 | D6: ZM82308CAB139 | E6: Machine | F6: 8500 | G6: Replacement | H6: RSO09352 | I6: Processing | J6: [ZMA0111A-CA] Rotimatic Plus | K6: 0 | L6: 1 | M6: Return with Refund/Replacement | N6: ZM82308CAB139 roti count: 8500 Roller is not Moving | O6: ZM82308CAB139 ROTI COUNT:: 8500 ROLLER IS NOT MOVING
A7: 46237 | B7: Pranjal Jain | C7: RSO04838 | D7: ZM1251144CAW04488 | E7: Machine | F7: 609 | G7: Replacement | H7: RSO09351 | I7: Processing | J7: [ZNF0111AW-CA] Rotimatic Next (Black & White) | K7: 0 | L7: 1 | M7: Return with Refund/Replacement | N7: ZM1251144CAW04488 roti count: 609 Not powering on | O7: ZM1251144CAW04488 ROTI COUNT:: 609 NOT NOT POWERING ON
A8: 46234 | B8: Ashish Mehta | C8: 78106 | D8: ZM1260102CAG08113 | E8: Machine | F8: 433 | G8: Replacement | H8: RSO09350 | I8: Processing | J8: [ZNF0111AG-CA] Rotimatic Next (Black & Grey) | K8: 0 | L8: 1 | M8: Return with Refund/Replacement | N8: ZM1260102CAG08113 roti count: 433 Not powering on | O8: ZM1260102CAG08113 ROTI COUNT:: 433 NOT NOT POWERING ON
A9: 46234 | B9: Rohit Yadav | C9: 62977 | D9: ZM1250416CAG00186 | E9: Machine | F9: 712 | G9: Replacement | H9: RSO09349 | I9: Processing | J9: [ZMA0111A-CA] Rotimatic Plus | K9: 0 | L9: 1 | M9: Return with Refund/Replacement | N9: ZM1250416CAG00186 roti count: 712 Transfer Arm Stuck | O9: ZM1250416CAG00186 ROTI COUNT:: 712 TRANSFER ARM STUCK
A10: 46234 | B10: Brigade People Pty Ltd | C10: 68935 | D10: ZM1250835MEW00868 | E10: Machine | F10: 0 | G10: Replacement | H10: RSO09348 | I10: Processing | J10: [ZNF0111AW-ME] Rotimatic Next (Black & White) | K10: 172.46627 | L10: 1 | M10: Return with Refund/Replacement | N10: ZM1250835MEW00868 roti count: 0 Knead Blade Stuck | O10: ZM1250835MEW00868 ROTI COUNT:: 0 KNEADER BLADE STUCK
A11: 46234 | B11: sateesh vadde | C11: 71143 | D11: ZM1251043CAG03935 | E11: Machine | F11: 0 | G11: Replacement | H11: RSO09347 | I11: Processing | J11: [ZNF0111AG-CA] Rotimatic Next (Black & Grey) | K11: 211.14687 | L11: 1 | M11: Return with Refund/Replacement | N11: ZM1251043CAG03935 roti count: 0 Transfer Arm Stuck | O11: ZM1251043CAG03935 ROTI COUNT:: 0 TRANSFER ARM STUCK
A12: 46234 | B12: Ashleye Soanes | C12: 80569 | D12: ZM1260311CAW09995 | E12: Machine | F12: 0 | G12: Replacement | H12: RSO09346 | I12: Processing | J12: [ZNF0111AW-CA] Rotimatic Next (Black & White) | K12: 54.064898 | L12: 1 | M12: Return with Refund/Replacement | N12: ZM1260311CAW09995 roti count: 0 Transfer Arm Stuck | O12: ZM1260311CAW09995 ROTI COUNT:: 0 TRANSFER ARM STUCK
A13: 46234 | B13: varun_varmani@hotmail.com | C13: 76496 | D13: ZM1260209MEG03101 | E13: Machine | F13: 0 | G13: Replacement | H13: RSO09345 | I13: Processing | J13: [2YearRotimaticNextRotimaticCareWarranty] Rotimatic Next - Rotimatic Care Plus Warranty - 2 Years | K13: 124.93907 | L13: 1 | M13: Return with Refund/Replacement | N13: ZM1260209MEG03101 roti count: 0 Transfer Arm Stuck | O13: ZM1260209MEG03101 ROTI COUNT:: 0 TRANSFER ARM STUCK
... A19: 46234 | B19: Munish Minocha | C19: 79729 | D19: ZM1260311CAW09988 | E19: Machine | F19: 0 | G19: Replacement | H19: RSO09339 | I19: Processing | J19: [ZNF0111AW-CA] Rotimatic Next (Black & White) | K19: 48.332764 | L19: 1 | M19: Return with Refund/Replacement | N19: ZM1260311CAW09988 roti count: 0 Not Powering On | O19: ZM1260311CAW09988 ROTI COUNT:: 0 NOT NOT POWERING ON
A20: 46233 | B20: vidhi modi | C20: 70306 | D20: ZM1251043CAG03932 | G20: Refund with Return | I20: Submitted | J20: [6MonthsRotimaticNextRotimaticCareWarranty] Rotimatic Next - Rotimatic Care Plus Warranty - 6 Months | K20: 0 | L20: 1 | M20: Cancellation | N20: Current Machine Serial Number: ZM1251043CAG03932 Roti Count: Unable to check the tool is not working Main Issue: Machine Related Issue Type: Not powering ON Replacement Received Count: 0 Troubleshooting Done: Y Tech Agent Name Handled: Meenakshi C Call handled by Raja Ravi Verma | O20: CURRENT MACHINE NUMBER ZM1251043CAG03932 ROTI COUNT:: UNABLE TO CHECK THE TOOL IS NOT WORKING MAIN ISSUE: MACHINE RELATED ISSUE TYPE: NOT NOT POWERING ON REPLACEMENT RECEIVED COUNT: 0 TROUBLESHOOTING DONE: Y TECH AGENT NAME HANDLED: MEENAKSHI C CALL HANDLED BY RAJA RAVI VERMA
A21: 46233 | B21: Sayali Autade | C21: 74763 | D21: ZM1251250CAW06779 | E21: Machine | F21: 1914 | G21: Replacement | H21: RSO09338 | I21: Processing | J21: [2YearRotimaticNextRotimaticCareWarranty] Rotimatic Next - Rotimatic Care Plus Warranty - 2 Years | K21: 40.323754 | L21: 1 | M21: Return with Refund/Replacement | N21: ZM1251250CAW06779 roti count: 1914 Kneading Tray Stuck | O21: ZM1251250CAW06779 ROTI COUNT:: 1914 KNEADING TRAY STUCK
